<?xml version="1.0" ?>
<!-- =================================================================================== -->
<!-- |    This document was autogenerated by xacro from bot.xacro                      | -->
<!-- |    EDITING THIS FILE BY HAND IS NOT RECOMMENDED                                 | -->
<!-- =================================================================================== -->
<robot name="socks_bot">
  <material name="yellow">
    <color rgba="1 1 0.0 1.0"/>
  </material>
  <material name="black">
    <color rgba="0.01 0.01 0.01 1.0"/>
  </material>
  <material name="red">
    <color rgba="0.5 0.0 0.0 1.0"/>
  </material>
  <link name="base_link">
    <!-- База -->
    <visual>
      <origin rpy="0 0 0" xyz="0 0 0"/>
      <geometry>
        <mesh filename="package://socks_bot/description/meshes/base.stl"/>
      </geometry>
      <material name="yellow"/>
    </visual>
    <!-- Мотор -->
    <visual>
      <origin rpy="1.5707963267948966 0 -1.5707963267948966" xyz="0.06 0.045 0.01625"/>
      <geometry>
        <mesh filename="package://socks_bot/description/meshes/tt_motor.stl" scale="1 1 1"/>
      </geometry>
      <material name="yellow"/>
    </visual>
    <visual>
      <origin rpy="1.5707963267948966 0 -1.5707963267948966" xyz="-0.06 0.045 0.01625"/>
      <geometry>
        <mesh filename="package://socks_bot/description/meshes/tt_motor.stl" scale="1 1 1"/>
      </geometry>
      <material name="yellow"/>
    </visual>
    <visual>
      <origin rpy="0 0 -1.5707963267948966" xyz="0 -0.03 0.105"/>
      <geometry>
        <mesh filename="package://socks_bot/description/meshes/cover.stl" scale="1 1 1"/>
      </geometry>
      <material name="yellow"/>
    </visual>
    <visual>
      <origin rpy="0.7853981633974483 0 0" xyz="-0.0365 -0.128 0.068"/>
      <geometry>
        <mesh filename="package://socks_bot/description/meshes/raspberry_holder.stl" scale="1 1 1"/>
      </geometry>
      <material name="yellow"/>
    </visual>
    <visual>
      <origin rpy="0 0 0" xyz="0 -0.125 0.0327"/>
      <geometry>
        <mesh filename="package://socks_bot/description/meshes/wheel_holder.stl" scale="1 1 1"/>
      </geometry>
      <material name="yellow"/>
    </visual>
    <!-- Коллизия -->
    <collision>
      <origin rpy="0 0 0" xyz="0 0 0"/>
      <geometry>
        <mesh filename="package://socks_bot/description/meshes/base.stl"/>
      </geometry>
    </collision>
  </link>
  <link name="wheel_left_link">
    <visual>
      <origin rpy="0 0 0" xyz="0 0 0"/>
      <geometry>
        <mesh filename="package://socks_bot/description/meshes/wheel.stl"/>
      </geometry>
      <material name="black"/>
    </visual>
    <collision>
      <origin rpy="0 0 0" xyz="0 0 0"/>
      <geometry>
        <mesh filename="package://socks_bot/description/meshes/wheel.stl"/>
      </geometry>
    </collision>
  </link>
  <joint name="wheel_left_joint" type="continuous">
    <parent link="base_link"/>
    <child link="wheel_left_link"/>
    <origin rpy="0 -1.5707963267948966 0" xyz="-0.102 0.034 0.01625"/>
    <axis xyz="1 0 0"/>
  </joint>
  <link name="wheel_right_link">
    <visual>
      <origin rpy="0 0 0" xyz="0 0 0"/>
      <geometry>
        <mesh filename="package://socks_bot/description/meshes/wheel.stl"/>
      </geometry>
      <material name="black"/>
    </visual>
    <collision>
      <origin rpy="0 0 0" xyz="0 0 0"/>
      <geometry>
        <mesh filename="package://socks_bot/description/meshes/wheel.stl"/>
      </geometry>
    </collision>
  </link>
  <joint name="wheel_right_joint" type="continuous">
    <parent link="base_link"/>
    <child link="wheel_right_link"/>
    <origin rpy="0 1.5707963267948966 0" xyz="0.102 0.034 0.01625"/>
    <axis xyz="1 0 0"/>
  </joint>
  <link name="caster_wheel">
    <visual>
      <origin rpy="0 0 3.141592653589793" xyz="0 0 0"/>
      <geometry>
        <mesh filename="package://socks_bot/description/meshes/caster_wheel.stl" scale="1 1 1"/>
      </geometry>
      <material name="red"/>
    </visual>
  </link>
  <joint name="caster_wheel_joint" type="fixed">
    <parent link="base_link"/>
    <child link="caster_wheel"/>
    <origin rpy="0 0 0" xyz="0 -0.14 -0.0"/>
    <axis xyz="1 0 0"/>
  </joint>
  <ros2_control name="MyRobotSystem" type="system">
    <hardware>
      <plugin>socks_bot/SocksBotHardware</plugin>
      <param name="wheel_radius">0.0325</param>
      <param name="wheel_separation">0.175</param>
    </hardware>
    <joint name="wheel_left_joint">
      <command_interface name="velocity"/>
      <state_interface name="position"/>
      <state_interface name="velocity"/>
    </joint>
    <joint name="wheel_right_joint">
      <command_interface name="velocity"/>
      <state_interface name="position"/>
      <state_interface name="velocity"/>
    </joint>
  </ros2_control>
</robot>
